Workbook
Name AsOfDate: Metrics!$C$50
Name CurrentPrice: Metrics!$C$4
Name MomentumStatus: Metrics!$C$78
Name RetDay: Metrics!$C$52
Name RetMonth: Metrics!$C$54
Name RetWeek: Metrics!$C$53
Name RetYTD: Metrics!$C$55
Name TrendStatus: Metrics!$C$77
Name VolatilityStatus: Metrics!$C$79

Sheet Dashboard
B1: GOLD — TECHNICAL ANALYSIS DASHBOARD
B2: ="XAU · As of "&TEXT(AsOfDate,"dd mmm yyyy")&" · Auto-updating workbook" -> 0
B3: Dashboard | C3: Trend | D3: Momentum | E3: Volatility | F3: S & R | G3: Matrix | H3: Outlook | I3: Data | J3: Read Me
B5: MARKET SNAPSHOT
B6: CURRENT PRICE | D6: DAILY | F6: WEEKLY | H6: MONTHLY | J6: YTD
B7: =CurrentPrice -> 0 | D7: =RetDay -> 0 | F7: =RetWeek -> 0 | H7: =RetMonth -> 0 | J7: =RetYTD -> 0
B10: MARKET REGIME
B11: TREND | E11: MOMENTUM | H11: VOLATILITY
B12: =TrendStatus -> 0 | E12: =MomentumStatus -> 0 | H12: =VolatilityStatus -> 0
B14: KEY LEVELS | G14: OUTLOOK
B15: Resistance 3 | D15: =IFERROR(Metrics!$C$65,"-") -> 0 | G15: Horizon | H15: Bias | J15: Target
B16: Resistance 2 | D16: =IFERROR(Metrics!$C$64,"-") -> 0 | G16: 1W | H16: =Metrics!$C$98 -> 0 | J16: =IFERROR(Metrics!$C$108,"-") -> 0
B17: Resistance 1 | D17: =IFERROR(Metrics!$C$63,"-") -> 0 | G17: 1M | H17: =Metrics!$D$98 -> 0 | J17: =IFERROR(Metrics!$D$108,"-") -> 0
B18: Support 1 | D18: =IFERROR(Metrics!$C$66,"-") -> 0 | G18: 3M | H18: =Metrics!$E$98 -> 0 | J18: =IFERROR(Metrics!$E$108,"-") -> 0
B19: Support 2 | D19: =IFERROR(Metrics!$C$67,"-") -> 0
B20: Support 3 | D20: =IFERROR(Metrics!$C$68,"-") -> 0

Sheet Trend
B1: TREND
B2: Moving-average structure and trend strength (daily).
B3: Dashboard | C3: Trend | D3: Momentum | E3: Volatility | F3: S & R | G3: Matrix | H3: Outlook | I3: Data | J3: Read Me
B5: MOVING AVERAGES (DAILY)
B6: Moving Average | C6: Value | D6: Price vs MA | E6: Position
B7: EMA20 | C7: =IFERROR(Metrics!$C$11,"-") -> 0 | D7: =IFERROR(Metrics!$C$4/Metrics!$C$11-1,"-") -> 0 | E7: =IF(Metrics!$C$4>Metrics!$C$11,"Above","Below") -> 0
B8: EMA50 | C8: =IFERROR(Metrics!$C$12,"-") -> 0 | D8: =IFERROR(Metrics!$C$4/Metrics!$C$12-1,"-") -> 0 | E8: =IF(Metrics!$C$4>Metrics!$C$12,"Above","Below") -> 0
B9: EMA100 | C9: =IFERROR(Metrics!$C$13,"-") -> 0 | D9: =IFERROR(Metrics!$C$4/Metrics!$C$13-1,"-") -> 0 | E9: =IF(Metrics!$C$4>Metrics!$C$13,"Above","Below") -> 0
B10: EMA200 | C10: =IFERROR(Metrics!$C$14,"-") -> 0 | D10: =IFERROR(Metrics!$C$4/Metrics!$C$14-1,"-") -> 0 | E10: =IF(Metrics!$C$4>Metrics!$C$14,"Above","Below") -> 0
B12: TREND SCORE
B13: Composite (-100 bearish … +100 bullish) | E13: =ROUND(AVERAGE(Metrics!$C$86:$C$89)/2*100,0) -> 0
B14: Trend status | E14: =TrendStatus -> 0

Sheet Momentum
B1: MOMENTUM
B2: Oscillators across timeframes (RSI, MACD, Stochastic, Stoch-RSI).
B3: Dashboard | C3: Trend | D3: Momentum | E3: Volatility | F3: S & R | G3: Matrix | H3: Outlook | I3: Data | J3: Read Me
B5: DAILY READINGS
B6: Indicator | D6: Value | F6: State
B7: RSI (14) | D7: =IFERROR(Metrics!$C$19,"-") -> 0 | F7: =IF(Metrics!$C$19="","-",IF(Metrics!$C$19>=70,"Overbought",IF(Metrics!$C$19<=30,"Oversold","Neutral"))) -> 0
B8: MACD | D8: =IFERROR(Metrics!$C$20,"-") -> 0 | F8: =IF(Metrics!$C$22="","-",IF(Metrics!$C$22>0,"Bullish","Bearish")) -> 0
B9: MACD signal | D9: =IFERROR(Metrics!$C$21,"-") -> 0 | F9: ="" -> 0
B10: Stochastic %K | D10: =IFERROR(Metrics!$C$23,"-") -> 0 | F10: =IF(Metrics!$C$23="","-",IF(Metrics!$C$23>=80,"Overbought",IF(Metrics!$C$23<=20,"Oversold","Neutral"))) -> 0
B11: Stoch-RSI %K | D11: =IFERROR(Metrics!$C$25,"-") -> 0 | F11: =IF(Metrics!$C$25="","-",IF(Metrics!$C$25>=80,"Overbought",IF(Metrics!$C$25<=20,"Oversold","Neutral"))) -> 0
B13: MULTI-TIMEFRAME SIGNAL
B14: Indicator | D14: Daily | E14: Weekly | F14: Monthly
B15: RSI | D15: =CHOOSE(Metrics!$C$81+3,"Bearish","Slightly Bearish","Neutral","Slightly Bullish","Bullish") -> 0 | E15: =CHOOSE(Metrics!$D$81+3,"Bearish","Slightly Bearish","Neutral","Slightly Bullish","Bullish") -> 0 | F15: =CHOOSE(Metrics!$E$81+3,"Bearish","Slightly Bearish","Neutral","Slightly Bullish","Bullish") -> 0
B16: MACD | D16: =CHOOSE(Metrics!$C$82+3,"Bearish","Slightly Bearish","Neutral","Slightly Bullish","Bullish") -> 0 | E16: =CHOOSE(Metrics!$D$82+3,"Bearish","Slightly Bearish","Neutral","Slightly Bullish","Bullish") -> 0 | F16: =CHOOSE(Metrics!$E$82+3,"Bearish","Slightly Bearish","Neutral","Slightly Bullish","Bullish") -> 0
B17: Stochastic | D17: =CHOOSE(Metrics!$C$83+3,"Bearish","Slightly Bearish","Neutral","Slightly Bullish","Bullish") -> 0 | E17: =CHOOSE(Metrics!$D$83+3,"Bearish","Slightly Bearish","Neutral","Slightly Bullish","Bullish") -> 0 | F17: =CHOOSE(Metrics!$E$83+3,"Bearish","Slightly Bearish","Neutral","Slightly Bullish","Bullish") -> 0
B18: Stoch RSI | D18: =CHOOSE(Metrics!$C$84+3,"Bearish","Slightly Bearish","Neutral","Slightly Bullish","Bullish") -> 0 | E18: =CHOOSE(Metrics!$D$84+3,"Bearish","Slightly Bearish","Neutral","Slightly Bullish","Bullish") -> 0 | F18: =CHOOSE(Metrics!$E$84+3,"Bearish","Slightly Bearish","Neutral","Slightly Bullish","Bullish") -> 0

Sheet Volatility
B1: VOLATILITY
B2: ATR, Bollinger Bands, historical volatility and regime.
B3: Dashboard | C3: Trend | D3: Momentum | E3: Volatility | F3: S & R | G3: Matrix | H3: Outlook | I3: Data | J3: Read Me
B5: DAILY READINGS
B6: Metric | E6: Value
B7: ATR (14) | E7: =IFERROR(Metrics!$C$30,"-") -> 0
B8: ATR % of price | E8: =IFERROR(Metrics!$C$30/Metrics!$C$4,"-") -> 0
B9: Bollinger bandwidth | E9: =IFERROR(Metrics!$C$35,"-") -> 0
B10: Bollinger %B | E10: =IFERROR(Metrics!$C$34,"-") -> 0
B11: Hist. vol (ann.) | E11: =IFERROR(Metrics!$C$39,"-") -> 0
B13: VOLATILITY REGIME
B14: Current regime | E14: =VolatilityStatus -> 0
B15: HV vs 100-bar average | E15: =IFERROR(Metrics!$C$39/Metrics!$C$49-1,"-") -> 0

Sheet Support & Resistance
B1: SUPPORT & RESISTANCE
B2: Swing levels, pivots, Fibonacci retracements and Donchian channel.
B3: Dashboard | C3: Trend | D3: Momentum | E3: Volatility | F3: S & R | G3: Matrix | H3: Outlook | I3: Data | J3: Read Me
B5: SWING LEVELS | F5: CLASSIC PIVOTS | J5: DONCHIAN (20)
B6: Level | D6: Price | F6: Level | H6: Price
B7: Resistance 3 | D7: =IFERROR(Metrics!$C$65,"-") -> 0 | F7: R3 | H7: =IFERROR(Metrics!$C$61,"-") -> 0 | J7: Upper | K7: =IFERROR(Metrics!$C$36,"-") -> 0
B8: Resistance 2 | D8: =IFERROR(Metrics!$C$64,"-") -> 0 | F8: R2 | H8: =IFERROR(Metrics!$C$59,"-") -> 0 | J8: Mid | K8: =IFERROR(Metrics!$C$38,"-") -> 0
B9: Resistance 1 | D9: =IFERROR(Metrics!$C$63,"-") -> 0 | F9: R1 | H9: =IFERROR(Metrics!$C$57,"-") -> 0 | J9: Lower | K9: =IFERROR(Metrics!$C$37,"-") -> 0
B10: Current price | D10: =IFERROR(Metrics!$C$4,"-") -> 0 | F10: Pivot (PP) | H10: =IFERROR(Metrics!$C$56,"-") -> 0
B11: Support 1 | D11: =IFERROR(Metrics!$C$66,"-") -> 0 | F11: S1 | H11: =IFERROR(Metrics!$C$58,"-") -> 0
B12: Support 2 | D12: =IFERROR(Metrics!$C$67,"-") -> 0 | F12: S2 | H12: =IFERROR(Metrics!$C$60,"-") -> 0
B13: Support 3 | D13: =IFERROR(Metrics!$C$68,"-") -> 0 | F13: S3 | H13: =IFERROR(Metrics!$C$62,"-") -> 0
B15: FIBONACCI RETRACEMENT (recent major swing)
B16: Ratio | D16: Price
B17: 0.0% | D17: =IFERROR(Metrics!$C$70,"-") -> 0
B18: 23.6% | D18: =IFERROR(Metrics!$C$71,"-") -> 0
B19: 38.2% | D19: =IFERROR(Metrics!$C$72,"-") -> 0
B20: 50.0% | D20: =IFERROR(Metrics!$C$73,"-") -> 0
B21: 61.8% | D21: =IFERROR(Metrics!$C$74,"-") -> 0
B22: 78.6% | D22: =IFERROR(Metrics!$C$75,"-") -> 0
B23: 100.0% | D23: =IFERROR(Metrics!$C$76,"-") -> 0
B25: Swing highs/lows use a confirmed 4-bar fractal. Resistance/Support pick the nearest confirmed swing levels above/below the current price. Fibonacci spans the most recent major swing within the last 100 bars; direction is detected automatically.

Sheet Matrix
B1: MULTI-TIMEFRAME INDICATOR MATRIX
B2: 14 indicators classified Bearish → Bullish on each timeframe.
B3: Dashboard | C3: Trend | D3: Momentum | E3: Volatility | F3: S & R | G3: Matrix | H3: Outlook | I3: Data | J3: Read Me
B5: INDICATOR MATRIX | G5: HORIZON SCORE
B6: Indicator | C6: Daily | D6: Weekly | E6: Monthly | G6: Horizon | H6: Score | I6: Bias
B7: RSI | C7: =CHOOSE(Metrics!$C$81+3,"Bearish","Slightly Bearish","Neutral","Slightly Bullish","Bullish") -> 0 | D7: =CHOOSE(Metrics!$D$81+3,"Bearish","Slightly Bearish","Neutral","Slightly Bullish","Bullish") -> 0 | E7: =CHOOSE(Metrics!$E$81+3,"Bearish","Slightly Bearish","Neutral","Slightly Bullish","Bullish") -> 0 | G7: Daily | H7: =Metrics!$C$97&"/100" -> 0 | I7: =Metrics!$C$98 -> 0
B8: MACD | C8: =CHOOSE(Metrics!$C$82+3,"Bearish","Slightly Bearish","Neutral","Slightly Bullish","Bullish") -> 0 | D8: =CHOOSE(Metrics!$D$82+3,"Bearish","Slightly Bearish","Neutral","Slightly Bullish","Bullish") -> 0 | E8: =CHOOSE(Metrics!$E$82+3,"Bearish","Slightly Bearish","Neutral","Slightly Bullish","Bullish") -> 0 | G8: Weekly | H8: =Metrics!$D$97&"/100" -> 0 | I8: =Metrics!$D$98 -> 0
B9: Stochastic | C9: =CHOOSE(Metrics!$C$83+3,"Bearish","Slightly Bearish","Neutral","Slightly Bullish","Bullish") -> 0 | D9: =CHOOSE(Metrics!$D$83+3,"Bearish","Slightly Bearish","Neutral","Slightly Bullish","Bullish") -> 0 | E9: =CHOOSE(Metrics!$E$83+3,"Bearish","Slightly Bearish","Neutral","Slightly Bullish","Bullish") -> 0 | G9: Monthly | H9: =Metrics!$E$97&"/100" -> 0 | I9: =Metrics!$E$98 -> 0
B10: Stoch RSI | C10: =CHOOSE(Metrics!$C$84+3,"Bearish","Slightly Bearish","Neutral","Slightly Bullish","Bullish") -> 0 | D10: =CHOOSE(Metrics!$D$84+3,"Bearish","Slightly Bearish","Neutral","Slightly Bullish","Bullish") -> 0 | E10: =CHOOSE(Metrics!$E$84+3,"Bearish","Slightly Bearish","Neutral","Slightly Bullish","Bullish") -> 0
B11: ADX/DMI | C11: =CHOOSE(Metrics!$C$85+3,"Bearish","Slightly Bearish","Neutral","Slightly Bullish","Bullish") -> 0 | D11: =CHOOSE(Metrics!$D$85+3,"Bearish","Slightly Bearish","Neutral","Slightly Bullish","Bullish") -> 0 | E11: =CHOOSE(Metrics!$E$85+3,"Bearish","Slightly Bearish","Neutral","Slightly Bullish","Bullish") -> 0
B12: EMA20 | C12: =CHOOSE(Metrics!$C$86+3,"Bearish","Slightly Bearish","Neutral","Slightly Bullish","Bullish") -> 0 | D12: =CHOOSE(Metrics!$D$86+3,"Bearish","Slightly Bearish","Neutral","Slightly Bullish","Bullish") -> 0 | E12: =CHOOSE(Metrics!$E$86+3,"Bearish","Slightly Bearish","Neutral","Slightly Bullish","Bullish") -> 0 | G12: SIGNAL BREAKDOWN
B13: EMA50 | C13: =CHOOSE(Metrics!$C$87+3,"Bearish","Slightly Bearish","Neutral","Slightly Bullish","Bullish") -> 0 | D13: =CHOOSE(Metrics!$D$87+3,"Bearish","Slightly Bearish","Neutral","Slightly Bullish","Bullish") -> 0 | E13: =CHOOSE(Metrics!$E$87+3,"Bearish","Slightly Bearish","Neutral","Slightly Bullish","Bullish") -> 0 | H13: Bullish | I13: Neutral | J13: Bearish
B14: EMA100 | C14: =CHOOSE(Metrics!$C$88+3,"Bearish","Slightly Bearish","Neutral","Slightly Bullish","Bullish") -> 0 | D14: =CHOOSE(Metrics!$D$88+3,"Bearish","Slightly Bearish","Neutral","Slightly Bullish","Bullish") -> 0 | E14: =CHOOSE(Metrics!$E$88+3,"Bearish","Slightly Bearish","Neutral","Slightly Bullish","Bullish") -> 0 | G14: Daily | H14: =Metrics!$C$102 -> 0 | I14: =Metrics!$C$103 -> 0 | J14: =Metrics!$C$104 -> 0
B15: EMA200 | C15: =CHOOSE(Metrics!$C$89+3,"Bearish","Slightly Bearish","Neutral","Slightly Bullish","Bullish") -> 0 | D15: =CHOOSE(Metrics!$D$89+3,"Bearish","Slightly Bearish","Neutral","Slightly Bullish","Bullish") -> 0 | E15: =CHOOSE(Metrics!$E$89+3,"Bearish","Slightly Bearish","Neutral","Slightly Bullish","Bullish") -> 0 | G15: Weekly | H15: =Metrics!$D$102 -> 0 | I15: =Metrics!$D$103 -> 0 | J15: =Metrics!$D$104 -> 0
B16: Ichimoku | C16: =CHOOSE(Metrics!$C$90+3,"Bearish","Slightly Bearish","Neutral","Slightly Bullish","Bullish") -> 0 | D16: =CHOOSE(Metrics!$D$90+3,"Bearish","Slightly Bearish","Neutral","Slightly Bullish","Bullish") -> 0 | E16: =CHOOSE(Metrics!$E$90+3,"Bearish","Slightly Bearish","Neutral","Slightly Bullish","Bullish") -> 0 | G16: Monthly | H16: =Metrics!$E$102 -> 0 | I16: =Metrics!$E$103 -> 0 | J16: =Metrics!$E$104 -> 0
B17: Bollinger Bands | C17: =CHOOSE(Metrics!$C$91+3,"Bearish","Slightly Bearish","Neutral","Slightly Bullish","Bullish") -> 0 | D17: =CHOOSE(Metrics!$D$91+3,"Bearish","Slightly Bearish","Neutral","Slightly Bullish","Bullish") -> 0 | E17: =CHOOSE(Metrics!$E$91+3,"Bearish","Slightly Bearish","Neutral","Slightly Bullish","Bullish") -> 0
B18: Donchian Channel | C18: =CHOOSE(Metrics!$C$92+3,"Bearish","Slightly Bearish","Neutral","Slightly Bullish","Bullish") -> 0 | D18: =CHOOSE(Metrics!$D$92+3,"Bearish","Slightly Bearish","Neutral","Slightly Bullish","Bullish") -> 0 | E18: =CHOOSE(Metrics!$E$92+3,"Bearish","Slightly Bearish","Neutral","Slightly Bullish","Bullish") -> 0
B19: Fibonacci | C19: =CHOOSE(Metrics!$C$93+3,"Bearish","Slightly Bearish","Neutral","Slightly Bullish","Bullish") -> 0 | D19: =CHOOSE(Metrics!$D$93+3,"Bearish","Slightly Bearish","Neutral","Slightly Bullish","Bullish") -> 0 | E19: =CHOOSE(Metrics!$E$93+3,"Bearish","Slightly Bearish","Neutral","Slightly Bullish","Bullish") -> 0
B20: Regression Channel | C20: =CHOOSE(Metrics!$C$94+3,"Bearish","Slightly Bearish","Neutral","Slightly Bullish","Bullish") -> 0 | D20: =CHOOSE(Metrics!$D$94+3,"Bearish","Slightly Bearish","Neutral","Slightly Bullish","Bullish") -> 0 | E20: =CHOOSE(Metrics!$E$94+3,"Bearish","Slightly Bearish","Neutral","Slightly Bullish","Bullish") -> 0

Sheet Outlook
B1: OUTLOOK
B2: Forward view derived from the indicator matrix and volatility.
B3: Dashboard | C3: Trend | D3: Momentum | E3: Volatility | F3: S & R | G3: Matrix | H3: Outlook | I3: Data | J3: Read Me
B5: DIRECTIONAL OUTLOOK
B6: Horizon | C6: Bias | E6: Target Price | G6: Expected Range | I6: Confidence
B7: 1 Week | C7: =Metrics!$C$98 -> 0 | E7: =IFERROR(Metrics!$C$108,"-") -> 0 | G7: =IFERROR(TEXT(Metrics!$C$109,"#,##0")&" - "&TEXT(Metrics!$C$110,"#,##0"),"-") -> 0 | I7: =IFERROR(TEXT(Metrics!$C$111/100,"0%")&" ("&IF(Metrics!$C$111>=66,"High",IF(Metrics!$C$111>=40,"Medium","Low"))&")","-") -> 0
B8: 1 Month | C8: =Metrics!$D$98 -> 0 | E8: =IFERROR(Metrics!$D$108,"-") -> 0 | G8: =IFERROR(TEXT(Metrics!$D$109,"#,##0")&" - "&TEXT(Metrics!$D$110,"#,##0"),"-") -> 0 | I8: =IFERROR(TEXT(Metrics!$D$111/100,"0%")&" ("&IF(Metrics!$D$111>=66,"High",IF(Metrics!$D$111>=40,"Medium","Low"))&")","-") -> 0
B9: 3 Months | C9: =Metrics!$E$98 -> 0 | E9: =IFERROR(Metrics!$E$108,"-") -> 0 | G9: =IFERROR(TEXT(Metrics!$E$109,"#,##0")&" - "&TEXT(Metrics!$E$110,"#,##0"),"-") -> 0 | I9: =IFERROR(TEXT(Metrics!$E$111/100,"0%")&" ("&IF(Metrics!$E$111>=66,"High",IF(Metrics!$E$111>=40,"Medium","Low"))&")","-") -> 0
B12: METHOD
B13: Bias for each horizon comes from the matrix horizon score (1 Week ← Daily, 1 Month ← Weekly, 3 Months ← Monthly). The target applies a volatility-scaled drift in the direction of bias; the expected range is a ±1-sigma band using annualised historical volatility scaled to the horizon (5 / 21 / 63 trading days). Confidence reflects how far the horizon score sits from neutral (50). All figures recompute automatically from the Data sheet.
C18: 1 Week | D18: 1 Month | E18: 3 Months
B19: High | C19: =IFERROR(Metrics!$C$110,"-") -> 0 | D19: =IFERROR(Metrics!$D$110,"-") -> 0 | E19: =IFERROR(Metrics!$E$110,"-") -> 0
B20: Target | C20: =IFERROR(Metrics!$C$108,"-") -> 0 | D20: =IFERROR(Metrics!$D$108,"-") -> 0 | E20: =IFERROR(Metrics!$E$108,"-") -> 0
B21: Low | C21: =IFERROR(Metrics!$C$109,"-") -> 0 | D21: =IFERROR(Metrics!$D$109,"-") -> 0 | E21: =IFERROR(Metrics!$E$109,"-") -> 0

Sheet Data
A1: Date | B1: Open | C1: High | D1: Low | E1: Close | G1: INPUT SHEET — paste your gold OHLC history here.
A2: 45712 | B2: 1852.84 | C2: 1854.52 | D2: 1843.92 | E2: 1846.25 | G2: Columns must stay in this order: Date | Open | High | Low | Close. Dates oldest→newest (top to bottom). To use your own data: select the sample rows below the header and paste over them; the table and every other sheet update automatically. The engine supports up to 2,000 daily rows. The data shipped here is SAMPLE data — replace it. See the 'Read Me' sheet for details.
A3: 45713 | B3: 1845.07 | C3: 1853.27 | D3: 1827.63 | E3: 1830.74
A4: 45714 | B4: 1832.11 | C4: 1852.52 | D4: 1830.75 | E4: 1849.6
A5: 45715 | B5: 1854.35 | C5: 1858.11 | D5: 1817.65 | E5: 1821.29
A6: 45716 | B6: 1811.78 | C6: 1818.23 | D6: 1789.61 | E6: 1792.97
A7: 45719 | B7: 1792.72 | C7: 1802.65 | D7: 1788.12 | E7: 1798.9
A8: 45720 | B8: 1801.03 | C8: 1809.68 | D8: 1788.66 | E8: 1804.91
A9: 45721 | B9: 1811.4 | C9: 1819.71 | D9: 1806.04 | E9: 1815.2
A10: 45722 | B10: 1814.62 | C10: 1819.21 | D10: 1808.2 | E10: 1810
A11: 45723 | B11: 1804.81 | C11: 1808.57 | D11: 1794.24 | E11: 1803.05
A12: 45726 | B12: 1804.37 | C12: 1807.45 | D12: 1779.31 | E12: 1789.98
A13: 45727 | B13: 1797.01 | C13: 1811.48 | D13: 1789.21 | E13: 1791.52
A14: 45728 | B14: 1787.13 | C14: 1793.99 | D14: 1786.69 | E14: 1790.43
... A341: 46185 | B341: 2523.11 | C341: 2532.97 | D341: 2510.7 | E341: 2515.82

Sheet Read Me
B1: GOLD TECHNICAL ANALYSIS — WORKBOOK GUIDE
B2: Institutional-style, fully self-updating technical model for gold (XAU).
B3: Dashboard | C3: Trend | D3: Momentum | E3: Volatility | F3: S & R | G3: Matrix | H3: Outlook | I3: Data | J3: Read Me
B5: HOW TO USE
B6: 1. Open the 'Data' sheet — it is the ONLY place you enter anything.
B7: 2. Paste your gold price history with columns in this exact order: Date | Open | High | Low | Close.
B8: 3. Keep dates sorted oldest → newest (top to bottom). Daily bars are expected.
B9: 4. Replace the shipped SAMPLE data: select the sample rows under the header and paste over them.
B10: 5. Everything else (Dashboard, Trend, Momentum, Volatility, Support & Resistance, Matrix, Outlook)
B11: recalculates automatically. No buttons, no macros, no manual steps.
B13: WHAT IS CALCULATED
B14: Trend | D14: EMA 20 / 50 / 100 / 200, price-vs-MA position, EMA slope, composite trend score.
B15: Momentum | D15: RSI(14), MACD(12,26,9), Stochastic %K/%D (14,3), Stochastic-RSI(14).
B16: Volatility | D16: ATR(14), Bollinger Bands(20,2), 20-bar historical volatility (annualised), volatility regime.
B17: Support / Resistance | D17: Fractal swing highs/lows, classic pivots, Fibonacci retracements, Donchian(20).
B18: Multi-Timeframe Matrix | D18: 14 indicators classified Bearish→Bullish on Daily, Weekly and Monthly resampled data.
B19: Outlook | D19: 1-week / 1-month / 3-month bias, target, expected range and confidence.
B21: METHOD NOTES & ASSUMPTIONS
B22: • Weekly and monthly series are resampled from your daily data inside the hidden engine (week = Mon–Fri grouping).
B23: • RSI / ATR / ADX use simple-moving-average smoothing (Cutler's method) for clean, stable spreadsheet formulas.
B24: • EMAs are seeded from the first available price and converge as history grows; supply ample history for EMA200.
B25: • An EMA is only classified once its timeframe has enough bars (EMA20→20, 50→50, 100→100, 200→200); otherwise it
B26: scores Neutral, so under-warmed Weekly/Monthly EMAs cannot inflate bias.
B27: • Ichimoku cloud uses the standard 9/26/52 settings; the cloud is read 26 bars back for the price-vs-cloud signal.
B28: • Classification maps each indicator to a -2..+2 score; a horizon score (0–100) is the rescaled average of 14 indicators.
B29: • Trend Status uses the same daily EMA composite as the Trend Score: |score| ≥ 50 ⇒ up/down trend, else SIDEWAYS.
B30: • Outlook targets/ranges are derived from horizon bias and historical volatility (±1σ scaled by horizon).
B31: • Engine capacity: up to 2,000 daily / 440 weekly / 120 monthly bars. Hidden engine sheets
B32: (Calc_Daily/Weekly/Monthly, ChartData, Metrics) can be unhidden to inspect every formula.
... B35: DISCLAIMER — For research and educational purposes only. Technical analysis is not investment advice. Markets involve risk; validate all figures before relying on them.

Sheet ChartData
A1: Date | B1: Open | C1: High | D1: Low | E1: Close | F1: EMA20 | G1: EMA50 | H1: EMA100 | I1: EMA200 | J1: RSI | K1: RSI70 | L1: RSI30 | M1: MACD | N1: Signal | O1: Hist | P1: BBup | Q1: BBmid | R1: BBlow | S1: ATR | T1: HV | U1: DonUp | V1: DonLow
A2: =IF((Metrics!$H$1-180+1)<1,"",INDEX(Calc_Daily!$A$2:$A$2001,(Metrics!$H$1-180+1))) -> 0 | B2: =IF((Metrics!$H$1-180+1)<1,"",INDEX(Calc_Daily!$B$2:$B$2001,(Metrics!$H$1-180+1))) -> 0 | C2: =IF((Metrics!$H$1-180+1)<1,"",INDEX(Calc_Daily!$C$2:$C$2001,(Metrics!$H$1-180+1))) -> 0 | D2: =IF((Metrics!$H$1-180+1)<1,"",INDEX(Calc_Daily!$D$2:$D$2001,(Metrics!$H$1-180+1))) -> 0 | E2: =IF((Metrics!$H$1-180+1)<1,"",INDEX(Calc_Daily!$E$2:$E$2001,(Metrics!$H$1-180+1))) -> 0 | F2: =IF((Metrics!$H$1-180+1)<1,"",INDEX(Calc_Daily!$H$2:$H$2001,(Metrics!$H$1-180+1))) -> 0 | G2: =IF((Metrics!$H$1-180+1)<1,"",INDEX(Calc_Daily!$I$2:$I$2001,(Metrics!$H$1-180+1))) -> 0 | H2: =IF((Metrics!$H$1-180+1)<1,"",INDEX(Calc_Daily!$J$2:$J$2001,(Metrics!$H$1-180+1))) -> 0 | I2: =IF((Metrics!$H$1-180+1)<1,"",INDEX(Calc_Daily!$K$2:$K$2001,(Metrics!$H$1-180+1))) -> 0 | J2: =IF((Metrics!$H$1-180+1)<1,"",INDEX(Calc_Daily!$N$2:$N$2001,(Metrics!$H$1-180+1))) -> 0 | K2: =IF((Metrics!$H$1-180+1)<1,"",70) -> 0 | L2: =IF((Metrics!$H$1-180+1)<1,"",30) -> 0 | M2: =IF((Metrics!$H$1-180+1)<1,"",INDEX(Calc_Daily!$Q$2:$Q$2001,(Metrics!$H$1-180+1))) -> 0 | N2: =IF((Metrics!$H$1-180+1)<1,"",INDEX(Calc_Daily!$R$2:$R$2001,(Metrics!$H$1-180+1))) -> 0 | O2: =IF((Metrics!$H$1-180+1)<1,"",INDEX(Calc_Daily!$S$2:$S$2001,(Metrics!$H$1-180+1))) -> 0 | P2: =IF((Metrics!$H$1-180+1)<1,"",INDEX(Calc_Daily!$AM$2:$AM$2001,(Metrics!$H$1-180+1))) -> 0 | Q2: =IF((Metrics!$H$1-180+1)<1,"",INDEX(Calc_Daily!$AK$2:$AK$2001,(Metrics!$H$1-180+1))) -> 0 | R2: =IF((Metrics!$H$1-180+1)<1,"",INDEX(Calc_Daily!$AN$2:$AN$2001,(Metrics!$H$1-180+1))) -> 0 | S2: =IF((Metrics!$H$1-180+1)<1,"",INDEX(Calc_Daily!$AD$2:$AD$2001,(Metrics!$H$1-180+1))) -> 0 | T2: =IF((Metrics!$H$1-180+1)<1,"",INDEX(Calc_Daily!$AT$2:$AT$2001,(Metrics!$H$1-180+1))) -> 0 | U2: =IF((Metrics!$H$1-180+1)<1,"",INDEX(Calc_Daily!$AQ$2:$AQ$2001,(Metrics!$H$1-180+1))) -> 0 | V2: =IF((Metrics!$H$1-180+1)<1,"",INDEX(Calc_Daily!$AR$2:$AR$2001,(Metrics!$H$1-180+1))) -> 0
A3: =IF((Metrics!$H$1-180+2)<1,"",INDEX(Calc_Daily!$A$2:$A$2001,(Metrics!$H$1-180+2))) -> 0 | B3: =IF((Metrics!$H$1-180+2)<1,"",INDEX(Calc_Daily!$B$2:$B$2001,(Metrics!$H$1-180+2))) -> 0 | C3: =IF((Metrics!$H$1-180+2)<1,"",INDEX(Calc_Daily!$C$2:$C$2001,(Metrics!$H$1-180+2))) -> 0 | D3: =IF((Metrics!$H$1-180+2)<1,"",INDEX(Calc_Daily!$D$2:$D$2001,(Metrics!$H$1-180+2))) -> 0 | E3: =IF((Metrics!$H$1-180+2)<1,"",INDEX(Calc_Daily!$E$2:$E$2001,(Metrics!$H$1-180+2))) -> 0 | F3: =IF((Metrics!$H$1-180+2)<1,"",INDEX(Calc_Daily!$H$2:$H$2001,(Metrics!$H$1-180+2))) -> 0 | G3: =IF((Metrics!$H$1-180+2)<1,"",INDEX(Calc_Daily!$I$2:$I$2001,(Metrics!$H$1-180+2))) -> 0 | H3: =IF((Metrics!$H$1-180+2)<1,"",INDEX(Calc_Daily!$J$2:$J$2001,(Metrics!$H$1-180+2))) -> 0 | I3: =IF((Metrics!$H$1-180+2)<1,"",INDEX(Calc_Daily!$K$2:$K$2001,(Metrics!$H$1-180+2))) -> 0 | J3: =IF((Metrics!$H$1-180+2)<1,"",INDEX(Calc_Daily!$N$2:$N$2001,(Metrics!$H$1-180+2))) -> 0 | K3: =IF((Metrics!$H$1-180+2)<1,"",70) -> 0 | L3: =IF((Metrics!$H$1-180+2)<1,"",30) -> 0 | M3: =IF((Metrics!$H$1-180+2)<1,"",INDEX(Calc_Daily!$Q$2:$Q$2001,(Metrics!$H$1-180+2))) -> 0 | N3: =IF((Metrics!$H$1-180+2)<1,"",INDEX(Calc_Daily!$R$2:$R$2001,(Metrics!$H$1-180+2))) -> 0 | O3: =IF((Metrics!$H$1-180+2)<1,"",INDEX(Calc_Daily!$S$2:$S$2001,(Metrics!$H$1-180+2))) -> 0 | P3: =IF((Metrics!$H$1-180+2)<1,"",INDEX(Calc_Daily!$AM$2:$AM$2001,(Metrics!$H$1-180+2))) -> 0 | Q3: =IF((Metrics!$H$1-180+2)<1,"",INDEX(Calc_Daily!$AK$2:$AK$2001,(Metrics!$H$1-180+2))) -> 0 | R3: =IF((Metrics!$H$1-180+2)<1,"",INDEX(Calc_Daily!$AN$2:$AN$2001,(Metrics!$H$1-180+2))) -> 0 | S3: =IF((Metrics!$H$1-180+2)<1,"",INDEX(Calc_Daily!$AD$2:$AD$2001,(Metrics!$H$1-180+2))) -> 0 | T3: =IF((Metrics!$H$1-180+2)<1,"",INDEX(Calc_Daily!$AT$2:$AT$2001,(Metrics!$H$1-180+2))) -> 0 | U3: =IF((Metrics!$H$1-180+2)<1,"",INDEX(Calc_Daily!$AQ$2:$AQ$2001,(Metrics!$H$1-180+2))) -> 0 | V3: =IF((Metrics!$H$1-180+2)<1,"",INDEX(Calc_Daily!$AR$2:$AR$2001,(Metrics!$H$1-180+2))) -> 0
A4: =IF((Metrics!$H$1-180+3)<1,"",INDEX(Calc_Daily!$A$2:$A$2001,(Metrics!$H$1-180+3))) -> 0 | B4: =IF((Metrics!$H$1-180+3)<1,"",INDEX(Calc_Daily!$B$2:$B$2001,(Metrics!$H$1-180+3))) -> 0 | C4: =IF((Metrics!$H$1-180+3)<1,"",INDEX(Calc_Daily!$C$2:$C$2001,(Metrics!$H$1-180+3))) -> 0 | D4: =IF((Metrics!$H$1-180+3)<1,"",INDEX(Calc_Daily!$D$2:$D$2001,(Metrics!$H$1-180+3))) -> 0 | E4: =IF((Metrics!$H$1-180+3)<1,"",INDEX(Calc_Daily!$E$2:$E$2001,(Metrics!$H$1-180+3))) -> 0 | F4: =IF((Metrics!$H$1-180+3)<1,"",INDEX(Calc_Daily!$H$2:$H$2001,(Metrics!$H$1-180+3))) -> 0 | G4: =IF((Metrics!$H$1-180+3)<1,"",INDEX(Calc_Daily!$I$2:$I$2001,(Metrics!$H$1-180+3))) -> 0 | H4: =IF((Metrics!$H$1-180+3)<1,"",INDEX(Calc_Daily!$J$2:$J$2001,(Metrics!$H$1-180+3))) -> 0 | I4: =IF((Metrics!$H$1-180+3)<1,"",INDEX(Calc_Daily!$K$2:$K$2001,(Metrics!$H$1-180+3))) -> 0 | J4: =IF((Metrics!$H$1-180+3)<1,"",INDEX(Calc_Daily!$N$2:$N$2001,(Metrics!$H$1-180+3))) -> 0 | K4: =IF((Metrics!$H$1-180+3)<1,"",70) -> 0 | L4: =IF((Metrics!$H$1-180+3)<1,"",30) -> 0 | M4: =IF((Metrics!$H$1-180+3)<1,"",INDEX(Calc_Daily!$Q$2:$Q$2001,(Metrics!$H$1-180+3))) -> 0 | N4: =IF((Metrics!$H$1-180+3)<1,"",INDEX(Calc_Daily!$R$2:$R$2001,(Metrics!$H$1-180+3))) -> 0 | O4: =IF((Metrics!$H$1-180+3)<1,"",INDEX(Calc_Daily!$S$2:$S$2001,(Metrics!$H$1-180+3))) -> 0 | P4: =IF((Metrics!$H$1-180+3)<1,"",INDEX(Calc_Daily!$AM$2:$AM$2001,(Metrics!$H$1-180+3))) -> 0 | Q4: =IF((Metrics!$H$1-180+3)<1,"",INDEX(Calc_Daily!$AK$2:$AK$2001,(Metrics!$H$1-180+3))) -> 0 | R4: =IF((Metrics!$H$1-180+3)<1,"",INDEX(Calc_Daily!$AN$2:$AN$2001,(Metrics!$H$1-180+3))) -> 0 | S4: =IF((Metrics!$H$1-180+3)<1,"",INDEX(Calc_Daily!$AD$2:$AD$2001,(Metrics!$H$1-180+3))) -> 0 | T4: =IF((Metrics!$H$1-180+3)<1,"",INDEX(Calc_Daily!$AT$2:$AT$2001,(Metrics!$H$1-180+3))) -> 0 | U4: =IF((Metrics!$H$1-180+3)<1,"",INDEX(Calc_Daily!$AQ$2:$AQ$2001,(Metrics!$H$1-180+3))) -> 0 | V4: =IF((Metrics!$H$1-180+3)<1,"",INDEX(Calc_Daily!$AR$2:$AR$2001,(Metrics!$H$1-180+3))) -> 0
A5: =IF((Metrics!$H$1-180+4)<1,"",INDEX(Calc_Daily!$A$2:$A$2001,(Metrics!$H$1-180+4))) -> 0 | B5: =IF((Metrics!$H$1-180+4)<1,"",INDEX(Calc_Daily!$B$2:$B$2001,(Metrics!$H$1-180+4))) -> 0 | C5: =IF((Metrics!$H$1-180+4)<1,"",INDEX(Calc_Daily!$C$2:$C$2001,(Metrics!$H$1-180+4))) -> 0 | D5: =IF((Metrics!$H$1-180+4)<1,"",INDEX(Calc_Daily!$D$2:$D$2001,(Metrics!$H$1-180+4))) -> 0 | E5: =IF((Metrics!$H$1-180+4)<1,"",INDEX(Calc_Daily!$E$2:$E$2001,(Metrics!$H$1-180+4))) -> 0 | F5: =IF((Metrics!$H$1-180+4)<1,"",INDEX(Calc_Daily!$H$2:$H$2001,(Metrics!$H$1-180+4))) -> 0 | G5: =IF((Metrics!$H$1-180+4)<1,"",INDEX(Calc_Daily!$I$2:$I$2001,(Metrics!$H$1-180+4))) -> 0 | H5: =IF((Metrics!$H$1-180+4)<1,"",INDEX(Calc_Daily!$J$2:$J$2001,(Metrics!$H$1-180+4))) -> 0 | I5: =IF((Metrics!$H$1-180+4)<1,"",INDEX(Calc_Daily!$K$2:$K$2001,(Metrics!$H$1-180+4))) -> 0 | J5: =IF((Metrics!$H$1-180+4)<1,"",INDEX(Calc_Daily!$N$2:$N$2001,(Metrics!$H$1-180+4))) -> 0 | K5: =IF((Metrics!$H$1-180+4)<1,"",70) -> 0 | L5: =IF((Metrics!$H$1-180+4)<1,"",30) -> 0 | M5: =IF((Metrics!$H$1-180+4)<1,"",INDEX(Calc_Daily!$Q$2:$Q$2001,(Metrics!$H$1-180+4))) -> 0 | N5: =IF((Metrics!$H$1-180+4)<1,"",INDEX(Calc_Daily!$R$2:$R$2001,(Metrics!$H$1-180+4))) -> 0 | O5: =IF((Metrics!$H$1-180+4)<1,"",INDEX(Calc_Daily!$S$2:$S$2001,(Metrics!$H$1-180+4))) -> 0 | P5: =IF((Metrics!$H$1-180+4)<1,"",INDEX(Calc_Daily!$AM$2:$AM$2001,(Metrics!$H$1-180+4))) -> 0 | Q5: =IF((Metrics!$H$1-180+4)<1,"",INDEX(Calc_Daily!$AK$2:$AK$2001,(Metrics!$H$1-180+4))) -> 0 | R5: =IF((Metrics!$H$1-180+4)<1,"",INDEX(Calc_Daily!$AN$2:$AN$2001,(Metrics!$H$1-180+4))) -> 0 | S5: =IF((Metrics!$H$1-180+4)<1,"",INDEX(Calc_Daily!$AD$2:$AD$2001,(Metrics!$H$1-180+4))) -> 0 | T5: =IF((Metrics!$H$1-180+4)<1,"",INDEX(Calc_Daily!$AT$2:$AT$2001,(Metrics!$H$1-180+4))) -> 0 | U5: =IF((Metrics!$H$1-180+4)<1,"",INDEX(Calc_Daily!$AQ$2:$AQ$2001,(Metrics!$H$1-180+4))) -> 0 | V5: =IF((Metrics!$H$1-180+4)<1,"",INDEX(Calc_Daily!$AR$2:$AR$2001,(Metrics!$H$1-180+4))) -> 0
A6: =IF((Metrics!$H$1-180+5)<1,"",INDEX(Calc_Daily!$A$2:$A$2001,(Metrics!$H$1-180+5))) -> 0 | B6: =IF((Metrics!$H$1-180+5)<1,"",INDEX(Calc_Daily!$B$2:$B$2001,(Metrics!$H$1-180+5))) -> 0 | C6: =IF((Metrics!$H$1-180+5)<1,"",INDEX(Calc_Daily!$C$2:$C$2001,(Metrics!$H$1-180+5))) -> 0 | D6: =IF((Metrics!$H$1-180+5)<1,"",INDEX(Calc_Daily!$D$2:$D$2001,(Metrics!$H$1-180+5))) -> 0 | E6: =IF((Metrics!$H$1-180+5)<1,"",INDEX(Calc_Daily!$E$2:$E$2001,(Metrics!$H$1-180+5))) -> 0 | F6: =IF((Metrics!$H$1-180+5)<1,"",INDEX(Calc_Daily!$H$2:$H$2001,(Metrics!$H$1-180+5))) -> 0 | G6: =IF((Metrics!$H$1-180+5)<1,"",INDEX(Calc_Daily!$I$2:$I$2001,(Metrics!$H$1-180+5))) -> 0 | H6: =IF((Metrics!$H$1-180+5)<1,"",INDEX(Calc_Daily!$J$2:$J$2001,(Metrics!$H$1-180+5))) -> 0 | I6: =IF((Metrics!$H$1-180+5)<1,"",INDEX(Calc_Daily!$K$2:$K$2001,(Metrics!$H$1-180+5))) -> 0 | J6: =IF((Metrics!$H$1-180+5)<1,"",INDEX(Calc_Daily!$N$2:$N$2001,(Metrics!$H$1-180+5))) -> 0 | K6: =IF((Metrics!$H$1-180+5)<1,"",70) -> 0 | L6: =IF((Metrics!$H$1-180+5)<1,"",30) -> 0 | M6: =IF((Metrics!$H$1-180+5)<1,"",INDEX(Calc_Daily!$Q$2:$Q$2001,(Metrics!$H$1-180+5))) -> 0 | N6: =IF((Metrics!$H$1-180+5)<1,"",INDEX(Calc_Daily!$R$2:$R$2001,(Metrics!$H$1-180+5))) -> 0 | O6: =IF((Metrics!$H$1-180+5)<1,"",INDEX(Calc_Daily!$S$2:$S$2001,(Metrics!$H$1-180+5))) -> 0 | P6: =IF((Metrics!$H$1-180+5)<1,"",INDEX(Calc_Daily!$AM$2:$AM$2001,(Metrics!$H$1-180+5))) -> 0 | Q6: =IF((Metrics!$H$1-180+5)<1,"",INDEX(Calc_Daily!$AK$2:$AK$2001,(Metrics!$H$1-180+5))) -> 0 | R6: =IF((Metrics!$H$1-180+5)<1,"",INDEX(Calc_Daily!$AN$2:$AN$2001,(Metrics!$H$1-180+5))) -> 0 | S6: =IF((Metrics!$H$1-180+5)<1,"",INDEX(Calc_Daily!$AD$2:$AD$2001,(Metrics!$H$1-180+5))) -> 0 | T6: =IF((Metrics!$H$1-180+5)<1,"",INDEX(Calc_Daily!$AT$2:$AT$2001,(Metrics!$H$1-180+5))) -> 0 | U6: =IF((Metrics!$H$1-180+5)<1,"",INDEX(Calc_Daily!$AQ$2:$AQ$2001,(Metrics!$H$1-180+5))) -> 0 | V6: =IF((Metrics!$H$1-180+5)<1,"",INDEX(Calc_Daily!$AR$2:$AR$2001,(Metrics!$H$1-180+5))) -> 0
A7: =IF((Metrics!$H$1-180+6)<1,"",INDEX(Calc_Daily!$A$2:$A$2001,(Metrics!$H$1-180+6))) -> 0 | B7: =IF((Metrics!$H$1-180+6)<1,"",INDEX(Calc_Daily!$B$2:$B$2001,(Metrics!$H$1-180+6))) -> 0 | C7: =IF((Metrics!$H$1-180+6)<1,"",INDEX(Calc_Daily!$C$2:$C$2001,(Metrics!$H$1-180+6))) -> 0 | D7: =IF((Metrics!$H$1-180+6)<1,"",INDEX(Calc_Daily!$D$2:$D$2001,(Metrics!$H$1-180+6))) -> 0 | E7: =IF((Metrics!$H$1-180+6)<1,"",INDEX(Calc_Daily!$E$2:$E$2001,(Metrics!$H$1-180+6))) -> 0 | F7: =IF((Metrics!$H$1-180+6)<1,"",INDEX(Calc_Daily!$H$2:$H$2001,(Metrics!$H$1-180+6))) -> 0 | G7: =IF((Metrics!$H$1-180+6)<1,"",INDEX(Calc_Daily!$I$2:$I$2001,(Metrics!$H$1-180+6))) -> 0 | H7: =IF((Metrics!$H$1-180+6)<1,"",INDEX(Calc_Daily!$J$2:$J$2001,(Metrics!$H$1-180+6))) -> 0 | I7: =IF((Metrics!$H$1-180+6)<1,"",INDEX(Calc_Daily!$K$2:$K$2001,(Metrics!$H$1-180+6))) -> 0 | J7: =IF((Metrics!$H$1-180+6)<1,"",INDEX(Calc_Daily!$N$2:$N$2001,(Metrics!$H$1-180+6))) -> 0 | K7: =IF((Metrics!$H$1-180+6)<1,"",70) -> 0 | L7: =IF((Metrics!$H$1-180+6)<1,"",30) -> 0 | M7: =IF((Metrics!$H$1-180+6)<1,"",INDEX(Calc_Daily!$Q$2:$Q$2001,(Metrics!$H$1-180+6))) -> 0 | N7: =IF((Metrics!$H$1-180+6)<1,"",INDEX(Calc_Daily!$R$2:$R$2001,(Metrics!$H$1-180+6))) -> 0 | O7: =IF((Metrics!$H$1-180+6)<1,"",INDEX(Calc_Daily!$S$2:$S$2001,(Metrics!$H$1-180+6))) -> 0 | P7: =IF((Metrics!$H$1-180+6)<1,"",INDEX(Calc_Daily!$AM$2:$AM$2001,(Metrics!$H$1-180+6))) -> 0 | Q7: =IF((Metrics!$H$1-180+6)<1,"",INDEX(Calc_Daily!$AK$2:$AK$2001,(Metrics!$H$1-180+6))) -> 0 | R7: =IF((Metrics!$H$1-180+6)<1,"",INDEX(Calc_Daily!$AN$2:$AN$2001,(Metrics!$H$1-180+6))) -> 0 | S7: =IF((Metrics!$H$1-180+6)<1,"",INDEX(Calc_Daily!$AD$2:$AD$2001,(Metrics!$H$1-180+6))) -> 0 | T7: =IF((Metrics!$H$1-180+6)<1,"",INDEX(Calc_Daily!$AT$2:$AT$2001,(Metrics!$H$1-180+6))) -> 0 | U7: =IF((Metrics!$H$1-180+6)<1,"",INDEX(Calc_Daily!$AQ$2:$AQ$2001,(Metrics!$H$1-180+6))) -> 0 | V7: =IF((Metrics!$H$1-180+6)<1,"",INDEX(Calc_Daily!$AR$2:$AR$2001,(Metrics!$H$1-180+6))) -> 0
A8: =IF((Metrics!$H$1-180+7)<1,"",INDEX(Calc_Daily!$A$2:$A$2001,(Metrics!$H$1-180+7))) -> 0 | B8: =IF((Metrics!$H$1-180+7)<1,"",INDEX(Calc_Daily!$B$2:$B$2001,(Metrics!$H$1-180+7))) -> 0 | C8: =IF((Metrics!$H$1-180+7)<1,"",INDEX(Calc_Daily!$C$2:$C$2001,(Metrics!$H$1-180+7))) -> 0 | D8: =IF((Metrics!$H$1-180+7)<1,"",INDEX(Calc_Daily!$D$2:$D$2001,(Metrics!$H$1-180+7))) -> 0 | E8: =IF((Metrics!$H$1-180+7)<1,"",INDEX(Calc_Daily!$E$2:$E$2001,(Metrics!$H$1-180+7))) -> 0 | F8: =IF((Metrics!$H$1-180+7)<1,"",INDEX(Calc_Daily!$H$2:$H$2001,(Metrics!$H$1-180+7))) -> 0 | G8: =IF((Metrics!$H$1-180+7)<1,"",INDEX(Calc_Daily!$I$2:$I$2001,(Metrics!$H$1-180+7))) -> 0 | H8: =IF((Metrics!$H$1-180+7)<1,"",INDEX(Calc_Daily!$J$2:$J$2001,(Metrics!$H$1-180+7))) -> 0 | I8: =IF((Metrics!$H$1-180+7)<1,"",INDEX(Calc_Daily!$K$2:$K$2001,(Metrics!$H$1-180+7))) -> 0 | J8: =IF((Metrics!$H$1-180+7)<1,"",INDEX(Calc_Daily!$N$2:$N$2001,(Metrics!$H$1-180+7))) -> 0 | K8: =IF((Metrics!$H$1-180+7)<1,"",70) -> 0 | L8: =IF((Metrics!$H$1-180+7)<1,"",30) -> 0 | M8: =IF((Metrics!$H$1-180+7)<1,"",INDEX(Calc_Daily!$Q$2:$Q$2001,(Metrics!$H$1-180+7))) -> 0 | N8: =IF((Metrics!$H$1-180+7)<1,"",INDEX(Calc_Daily!$R$2:$R$2001,(Metrics!$H$1-180+7))) -> 0 | O8: =IF((Metrics!$H$1-180+7)<1,"",INDEX(Calc_Daily!$S$2:$S$2001,(Metrics!$H$1-180+7))) -> 0 | P8: =IF((Metrics!$H$1-180+7)<1,"",INDEX(Calc_Daily!$AM$2:$AM$2001,(Metrics!$H$1-180+7))) -> 0 | Q8: =IF((Metrics!$H$1-180+7)<1,"",INDEX(Calc_Daily!$AK$2:$AK$2001,(Metrics!$H$1-180+7))) -> 0 | R8: =IF((Metrics!$H$1-180+7)<1,"",INDEX(Calc_Daily!$AN$2:$AN$2001,(Metrics!$H$1-180+7))) -> 0 | S8: =IF((Metrics!$H$1-180+7)<1,"",INDEX(Calc_Daily!$AD$2:$AD$2001,(Metrics!$H$1-180+7))) -> 0 | T8: =IF((Metrics!$H$1-180+7)<1,"",INDEX(Calc_Daily!$AT$2:$AT$2001,(Metrics!$H$1-180+7))) -> 0 | U8: =IF((Metrics!$H$1-180+7)<1,"",INDEX(Calc_Daily!$AQ$2:$AQ$2001,(Metrics!$H$1-180+7))) -> 0 | V8: =IF((Metrics!$H$1-180+7)<1,"",INDEX(Calc_Daily!$AR$2:$AR$2001,(Metrics!$H$1-180+7))) -> 0
A9: =IF((Metrics!$H$1-180+8)<1,"",INDEX(Calc_Daily!$A$2:$A$2001,(Metrics!$H$1-180+8))) -> 0 | B9: =IF((Metrics!$H$1-180+8)<1,"",INDEX(Calc_Daily!$B$2:$B$2001,(Metrics!$H$1-180+8))) -> 0 | C9: =IF((Metrics!$H$1-180+8)<1,"",INDEX(Calc_Daily!$C$2:$C$2001,(Metrics!$H$1-180+8))) -> 0 | D9: =IF((Metrics!$H$1-180+8)<1,"",INDEX(Calc_Daily!$D$2:$D$2001,(Metrics!$H$1-180+8))) -> 0 | E9: =IF((Metrics!$H$1-180+8)<1,"",INDEX(Calc_Daily!$E$2:$E$2001,(Metrics!$H$1-180+8))) -> 0 | F9: =IF((Metrics!$H$1-180+8)<1,"",INDEX(Calc_Daily!$H$2:$H$2001,(Metrics!$H$1-180+8))) -> 0 | G9: =IF((Metrics!$H$1-180+8)<1,"",INDEX(Calc_Daily!$I$2:$I$2001,(Metrics!$H$1-180+8))) -> 0 | H9: =IF((Metrics!$H$1-180+8)<1,"",INDEX(Calc_Daily!$J$2:$J$2001,(Metrics!$H$1-180+8))) -> 0 | I9: =IF((Metrics!$H$1-180+8)<1,"",INDEX(Calc_Daily!$K$2:$K$2001,(Metrics!$H$1-180+8))) -> 0 | J9: =IF((Metrics!$H$1-180+8)<1,"",INDEX(Calc_Daily!$N$2:$N$2001,(Metrics!$H$1-180+8))) -> 0 | K9: =IF((Metrics!$H$1-180+8)<1,"",70) -> 0 | L9: =IF((Metrics!$H$1-180+8)<1,"",30) -> 0 | M9: =IF((Metrics!$H$1-180+8)<1,"",INDEX(Calc_Daily!$Q$2:$Q$2001,(Metrics!$H$1-180+8))) -> 0 | N9: =IF((Metrics!$H$1-180+8)<1,"",INDEX(Calc_Daily!$R$2:$R$2001,(Metrics!$H$1-180+8))) -> 0 | O9: =IF((Metrics!$H$1-180+8)<1,"",INDEX(Calc_Daily!$S$2:$S$2001,(Metrics!$H$1-180+8))) -> 0 | P9: =IF((Metrics!$H$1-180+8)<1,"",INDEX(Calc_Daily!$AM$2:$AM$2001,(Metrics!$H$1-180+8))) -> 0 | Q9: =IF((Metrics!$H$1-180+8)<1,"",INDEX(Calc_Daily!$AK$2:$AK$2001,(Metrics!$H$1-180+8))) -> 0 | R9: =IF((Metrics!$H$1-180+8)<1,"",INDEX(Calc_Daily!$AN$2:$AN$2001,(Metrics!$H$1-180+8))) -> 0 | S9: =IF((Metrics!$H$1-180+8)<1,"",INDEX(Calc_Daily!$AD$2:$AD$2001,(Metrics!$H$1-180+8))) -> 0 | T9: =IF((Metrics!$H$1-180+8)<1,"",INDEX(Calc_Daily!$AT$2:$AT$2001,(Metrics!$H$1-180+8))) -> 0 | U9: =IF((Metrics!$H$1-180+8)<1,"",INDEX(Calc_Daily!$AQ$2:$AQ$2001,(Metrics!$H$1-180+8))) -> 0 | V9: =IF((Metrics!$H$1-180+8)<1,"",INDEX(Calc_Daily!$AR$2:$AR$2001,(Metrics!$H$1-180+8))) -> 0
A10: =IF((Metrics!$H$1-180+9)<1,"",INDEX(Calc_Daily!$A$2:$A$2001,(Metrics!$H$1-180+9))) -> 0 | B10: =IF((Metrics!$H$1-180+9)<1,"",INDEX(Calc_Daily!$B$2:$B$2001,(Metrics!$H$1-180+9))) -> 0 | C10: =IF((Metrics!$H$1-180+9)<1,"",INDEX(Calc_Daily!$C$2:$C$2001,(Metrics!$H$1-180+9))) -> 0 | D10: =IF((Metrics!$H$1-180+9)<1,"",INDEX(Calc_Daily!$D$2:$D$2001,(Metrics!$H$1-180+9))) -> 0 | E10: =IF((Metrics!$H$1-180+9)<1,"",INDEX(Calc_Daily!$E$2:$E$2001,(Metrics!$H$1-180+9))) -> 0 | F10: =IF((Metrics!$H$1-180+9)<1,"",INDEX(Calc_Daily!$H$2:$H$2001,(Metrics!$H$1-180+9))) -> 0 | G10: =IF((Metrics!$H$1-180+9)<1,"",INDEX(Calc_Daily!$I$2:$I$2001,(Metrics!$H$1-180+9))) -> 0 | H10: =IF((Metrics!$H$1-180+9)<1,"",INDEX(Calc_Daily!$J$2:$J$2001,(Metrics!$H$1-180+9))) -> 0 | I10: =IF((Metrics!$H$1-180+9)<1,"",INDEX(Calc_Daily!$K$2:$K$2001,(Metrics!$H$1-180+9))) -> 0 | J10: =IF((Metrics!$H$1-180+9)<1,"",INDEX(Calc_Daily!$N$2:$N$2001,(Metrics!$H$1-180+9))) -> 0 | K10: =IF((Metrics!$H$1-180+9)<1,"",70) -> 0 | L10: =IF((Metrics!$H$1-180+9)<1,"",30) -> 0 | M10: =IF((Metrics!$H$1-180+9)<1,"",INDEX(Calc_Daily!$Q$2:$Q$2001,(Metrics!$H$1-180+9))) -> 0 | N10: =IF((Metrics!$H$1-180+9)<1,"",INDEX(Calc_Daily!$R$2:$R$2001,(Metrics!$H$1-180+9))) -> 0 | O10: =IF((Metrics!$H$1-180+9)<1,"",INDEX(Calc_Daily!$S$2:$S$2001,(Metrics!$H$1-180+9))) -> 0 | P10: =IF((Metrics!$H$1-180+9)<1,"",INDEX(Calc_Daily!$AM$2:$AM$2001,(Metrics!$H$1-180+9))) -> 0 | Q10: =IF((Metrics!$H$1-180+9)<1,"",INDEX(Calc_Daily!$AK$2:$AK$2001,(Metrics!$H$1-180+9))) -> 0 | R10: =IF((Metrics!$H$1-180+9)<1,"",INDEX(Calc_Daily!$AN$2:$AN$2001,(Metrics!$H$1-180+9))) -> 0 | S10: =IF((Metrics!$H$1-180+9)<1,"",INDEX(Calc_Daily!$AD$2:$AD$2001,(Metrics!$H$1-180+9))) -> 0 | T10: =IF((Metrics!$H$1-180+9)<1,"",INDEX(Calc_Daily!$AT$2:$AT$2001,(Metrics!$H$1-180+9))) -> 0 | U10: =IF((Metrics!$H$1-180+9)<1,"",INDEX(Calc_Daily!$AQ$2:$AQ$2001,(Metrics!$H$1-180+9))) -> 0 | V10: =IF((Metrics!$H$1-180+9)<1,"",INDEX(Calc_Daily!$AR$2:$AR$2001,(Metrics!$H$1-180+9))) -> 0
A11: =IF((Metrics!$H$1-180+10)<1,"",INDEX(Calc_Daily!$A$2:$A$2001,(Metrics!$H$1-180+10))) -> 0 | B11: =IF((Metrics!$H$1-180+10)<1,"",INDEX(Calc_Daily!$B$2:$B$2001,(Metrics!$H$1-180+10))) -> 0 | C11: =IF((Metrics!$H$1-180+10)<1,"",INDEX(Calc_Daily!$C$2:$C$2001,(Metrics!$H$1-180+10))) -> 0 | D11: =IF((Metrics!$H$1-180+10)<1,"",INDEX(Calc_Daily!$D$2:$D$2001,(Metrics!$H$1-180+10))) -> 0 | E11: =IF((Metrics!$H$1-180+10)<1,"",INDEX(Calc_Daily!$E$2:$E$2001,(Metrics!$H$1-180+10))) -> 0 | F11: =IF((Metrics!$H$1-180+10)<1,"",INDEX(Calc_Daily!$H$2:$H$2001,(Metrics!$H$1-180+10))) -> 0 | G11: =IF((Metrics!$H$1-180+10)<1,"",INDEX(Calc_Daily!$I$2:$I$2001,(Metrics!$H$1-180+10))) -> 0 | H11: =IF((Metrics!$H$1-180+10)<1,"",INDEX(Calc_Daily!$J$2:$J$2001,(Metrics!$H$1-180+10))) -> 0 | I11: =IF((Metrics!$H$1-180+10)<1,"",INDEX(Calc_Daily!$K$2:$K$2001,(Metrics!$H$1-180+10))) -> 0 | J11: =IF((Metrics!$H$1-180+10)<1,"",INDEX(Calc_Daily!$N$2:$N$2001,(Metrics!$H$1-180+10))) -> 0 | K11: =IF((Metrics!$H$1-180+10)<1,"",70) -> 0 | L11: =IF((Metrics!$H$1-180+10)<1,"",30) -> 0 | M11: =IF((Metrics!$H$1-180+10)<1,"",INDEX(Calc_Daily!$Q$2:$Q$2001,(Metrics!$H$1-180+10))) -> 0 | N11: =IF((Metrics!$H$1-180+10)<1,"",INDEX(Calc_Daily!$R$2:$R$2001,(Metrics!$H$1-180+10))) -> 0 | O11: =IF((Metrics!$H$1-180+10)<1,"",INDEX(Calc_Daily!$S$2:$S$2001,(Metrics!$H$1-180+10))) -> 0 | P11: =IF((Metrics!$H$1-180+10)<1,"",INDEX(Calc_Daily!$AM$2:$AM$2001,(Metrics!$H$1-180+10))) -> 0 | Q11: =IF((Metrics!$H$1-180+10)<1,"",INDEX(Calc_Daily!$AK$2:$AK$2001,(Metrics!$H$1-180+10))) -> 0 | R11: =IF((Metrics!$H$1-180+10)<1,"",INDEX(Calc_Daily!$AN$2:$AN$2001,(Metrics!$H$1-180+10))) -> 0 | S11: =IF((Metrics!$H$1-180+10)<1,"",INDEX(Calc_Daily!$AD$2:$AD$2001,(Metrics!$H$1-180+10))) -> 0 | T11: =IF((Metrics!$H$1-180+10)<1,"",INDEX(Calc_Daily!$AT$2:$AT$2001,(Metrics!$H$1-180+10))) -> 0 | U11: =IF((Metrics!$H$1-180+10)<1,"",INDEX(Calc_Daily!$AQ$2:$AQ$2001,(Metrics!$H$1-180+10))) -> 0 | V11: =IF((Metrics!$H$1-180+10)<1,"",INDEX(Calc_Daily!$AR$2:$AR$2001,(Metrics!$H$1-180+10))) -> 0
A12: =IF((Metrics!$H$1-180+11)<1,"",INDEX(Calc_Daily!$A$2:$A$2001,(Metrics!$H$1-180+11))) -> 0 | B12: =IF((Metrics!$H$1-180+11)<1,"",INDEX(Calc_Daily!$B$2:$B$2001,(Metrics!$H$1-180+11))) -> 0 | C12: =IF((Metrics!$H$1-180+11)<1,"",INDEX(Calc_Daily!$C$2:$C$2001,(Metrics!$H$1-180+11))) -> 0 | D12: =IF((Metrics!$H$1-180+11)<1,"",INDEX(Calc_Daily!$D$2:$D$2001,(Metrics!$H$1-180+11))) -> 0 | E12: =IF((Metrics!$H$1-180+11)<1,"",INDEX(Calc_Daily!$E$2:$E$2001,(Metrics!$H$1-180+11))) -> 0 | F12: =IF((Metrics!$H$1-180+11)<1,"",INDEX(Calc_Daily!$H$2:$H$2001,(Metrics!$H$1-180+11))) -> 0 | G12: =IF((Metrics!$H$1-180+11)<1,"",INDEX(Calc_Daily!$I$2:$I$2001,(Metrics!$H$1-180+11))) -> 0 | H12: =IF((Metrics!$H$1-180+11)<1,"",INDEX(Calc_Daily!$J$2:$J$2001,(Metrics!$H$1-180+11))) -> 0 | I12: =IF((Metrics!$H$1-180+11)<1,"",INDEX(Calc_Daily!$K$2:$K$2001,(Metrics!$H$1-180+11))) -> 0 | J12: =IF((Metrics!$H$1-180+11)<1,"",INDEX(Calc_Daily!$N$2:$N$2001,(Metrics!$H$1-180+11))) -> 0 | K12: =IF((Metrics!$H$1-180+11)<1,"",70) -> 0 | L12: =IF((Metrics!$H$1-180+11)<1,"",30) -> 0 | M12: =IF((Metrics!$H$1-180+11)<1,"",INDEX(Calc_Daily!$Q$2:$Q$2001,(Metrics!$H$1-180+11))) -> 0 | N12: =IF((Metrics!$H$1-180+11)<1,"",INDEX(Calc_Daily!$R$2:$R$2001,(Metrics!$H$1-180+11))) -> 0 | O12: =IF((Metrics!$H$1-180+11)<1,"",INDEX(Calc_Daily!$S$2:$S$2001,(Metrics!$H$1-180+11))) -> 0 | P12: =IF((Metrics!$H$1-180+11)<1,"",INDEX(Calc_Daily!$AM$2:$AM$2001,(Metrics!$H$1-180+11))) -> 0 | Q12: =IF((Metrics!$H$1-180+11)<1,"",INDEX(Calc_Daily!$AK$2:$AK$2001,(Metrics!$H$1-180+11))) -> 0 | R12: =IF((Metrics!$H$1-180+11)<1,"",INDEX(Calc_Daily!$AN$2:$AN$2001,(Metrics!$H$1-180+11))) -> 0 | S12: =IF((Metrics!$H$1-180+11)<1,"",INDEX(Calc_Daily!$AD$2:$AD$2001,(Metrics!$H$1-180+11))) -> 0 | T12: =IF((Metrics!$H$1-180+11)<1,"",INDEX(Calc_Daily!$AT$2:$AT$2001,(Metrics!$H$1-180+11))) -> 0 | U12: =IF((Metrics!$H$1-180+11)<1,"",INDEX(Calc_Daily!$AQ$2:$AQ$2001,(Metrics!$H$1-180+11))) -> 0 | V12: =IF((Metrics!$H$1-180+11)<1,"",INDEX(Calc_Daily!$AR$2:$AR$2001,(Metrics!$H$1-180+11))) -> 0
A13: =IF((Metrics!$H$1-180+12)<1,"",INDEX(Calc_Daily!$A$2:$A$2001,(Metrics!$H$1-180+12))) -> 0 | B13: =IF((Metrics!$H$1-180+12)<1,"",INDEX(Calc_Daily!$B$2:$B$2001,(Metrics!$H$1-180+12))) -> 0 | C13: =IF((Metrics!$H$1-180+12)<1,"",INDEX(Calc_Daily!$C$2:$C$2001,(Metrics!$H$1-180+12))) -> 0 | D13: =IF((Metrics!$H$1-180+12)<1,"",INDEX(Calc_Daily!$D$2:$D$2001,(Metrics!$H$1-180+12))) -> 0 | E13: =IF((Metrics!$H$1-180+12)<1,"",INDEX(Calc_Daily!$E$2:$E$2001,(Metrics!$H$1-180+12))) -> 0 | F13: =IF((Metrics!$H$1-180+12)<1,"",INDEX(Calc_Daily!$H$2:$H$2001,(Metrics!$H$1-180+12))) -> 0 | G13: =IF((Metrics!$H$1-180+12)<1,"",INDEX(Calc_Daily!$I$2:$I$2001,(Metrics!$H$1-180+12))) -> 0 | H13: =IF((Metrics!$H$1-180+12)<1,"",INDEX(Calc_Daily!$J$2:$J$2001,(Metrics!$H$1-180+12))) -> 0 | I13: =IF((Metrics!$H$1-180+12)<1,"",INDEX(Calc_Daily!$K$2:$K$2001,(Metrics!$H$1-180+12))) -> 0 | J13: =IF((Metrics!$H$1-180+12)<1,"",INDEX(Calc_Daily!$N$2:$N$2001,(Metrics!$H$1-180+12))) -> 0 | K13: =IF((Metrics!$H$1-180+12)<1,"",70) -> 0 | L13: =IF((Metrics!$H$1-180+12)<1,"",30) -> 0 | M13: =IF((Metrics!$H$1-180+12)<1,"",INDEX(Calc_Daily!$Q$2:$Q$2001,(Metrics!$H$1-180+12))) -> 0 | N13: =IF((Metrics!$H$1-180+12)<1,"",INDEX(Calc_Daily!$R$2:$R$2001,(Metrics!$H$1-180+12))) -> 0 | O13: =IF((Metrics!$H$1-180+12)<1,"",INDEX(Calc_Daily!$S$2:$S$2001,(Metrics!$H$1-180+12))) -> 0 | P13: =IF((Metrics!$H$1-180+12)<1,"",INDEX(Calc_Daily!$AM$2:$AM$2001,(Metrics!$H$1-180+12))) -> 0 | Q13: =IF((Metrics!$H$1-180+12)<1,"",INDEX(Calc_Daily!$AK$2:$AK$2001,(Metrics!$H$1-180+12))) -> 0 | R13: =IF((Metrics!$H$1-180+12)<1,"",INDEX(Calc_Daily!$AN$2:$AN$2001,(Metrics!$H$1-180+12))) -> 0 | S13: =IF((Metrics!$H$1-180+12)<1,"",INDEX(Calc_Daily!$AD$2:$AD$2001,(Metrics!$H$1-180+12))) -> 0 | T13: =IF((Metrics!$H$1-180+12)<1,"",INDEX(Calc_Daily!$AT$2:$AT$2001,(Metrics!$H$1-180+12))) -> 0 | U13: =IF((Metrics!$H$1-180+12)<1,"",INDEX(Calc_Daily!$AQ$2:$AQ$2001,(Metrics!$H$1-180+12))) -> 0 | V13: =IF((Metrics!$H$1-180+12)<1,"",INDEX(Calc_Daily!$AR$2:$AR$2001,(Metrics!$H$1-180+12))) -> 0
A14: =IF((Metrics!$H$1-180+13)<1,"",INDEX(Calc_Daily!$A$2:$A$2001,(Metrics!$H$1-180+13))) -> 0 | B14: =IF((Metrics!$H$1-180+13)<1,"",INDEX(Calc_Daily!$B$2:$B$2001,(Metrics!$H$1-180+13))) -> 0 | C14: =IF((Metrics!$H$1-180+13)<1,"",INDEX(Calc_Daily!$C$2:$C$2001,(Metrics!$H$1-180+13))) -> 0 | D14: =IF((Metrics!$H$1-180+13)<1,"",INDEX(Calc_Daily!$D$2:$D$2001,(Metrics!$H$1-180+13))) -> 0 | E14: =IF((Metrics!$H$1-180+13)<1,"",INDEX(Calc_Daily!$E$2:$E$2001,(Metrics!$H$1-180+13))) -> 0 | F14: =IF((Metrics!$H$1-180+13)<1,"",INDEX(Calc_Daily!$H$2:$H$2001,(Metrics!$H$1-180+13))) -> 0 | G14: =IF((Metrics!$H$1-180+13)<1,"",INDEX(Calc_Daily!$I$2:$I$2001,(Metrics!$H$1-180+13))) -> 0 | H14: =IF((Metrics!$H$1-180+13)<1,"",INDEX(Calc_Daily!$J$2:$J$2001,(Metrics!$H$1-180+13))) -> 0 | I14: =IF((Metrics!$H$1-180+13)<1,"",INDEX(Calc_Daily!$K$2:$K$2001,(Metrics!$H$1-180+13))) -> 0 | J14: =IF((Metrics!$H$1-180+13)<1,"",INDEX(Calc_Daily!$N$2:$N$2001,(Metrics!$H$1-180+13))) -> 0 | K14: =IF((Metrics!$H$1-180+13)<1,"",70) -> 0 | L14: =IF((Metrics!$H$1-180+13)<1,"",30) -> 0 | M14: =IF((Metrics!$H$1-180+13)<1,"",INDEX(Calc_Daily!$Q$2:$Q$2001,(Metrics!$H$1-180+13))) -> 0 | N14: =IF((Metrics!$H$1-180+13)<1,"",INDEX(Calc_Daily!$R$2:$R$2001,(Metrics!$H$1-180+13))) -> 0 | O14: =IF((Metrics!$H$1-180+13)<1,"",INDEX(Calc_Daily!$S$2:$S$2001,(Metrics!$H$1-180+13))) -> 0 | P14: =IF((Metrics!$H$1-180+13)<1,"",INDEX(Calc_Daily!$AM$2:$AM$2001,(Metrics!$H$1-180+13))) -> 0 | Q14: =IF((Metrics!$H$1-180+13)<1,"",INDEX(Calc_Daily!$AK$2:$AK$2001,(Metrics!$H$1-180+13))) -> 0 | R14: =IF((Metrics!$H$1-180+13)<1,"",INDEX(Calc_Daily!$AN$2:$AN$2001,(Metrics!$H$1-180+13))) -> 0 | S14: =IF((Metrics!$H$1-180+13)<1,"",INDEX(Calc_Daily!$AD$2:$AD$2001,(Metrics!$H$1-180+13))) -> 0 | T14: =IF((Metrics!$H$1-180+13)<1,"",INDEX(Calc_Daily!$AT$2:$AT$2001,(Metrics!$H$1-180+13))) -> 0 | U14: =IF((Metrics!$H$1-180+13)<1,"",INDEX(Calc_Daily!$AQ$2:$AQ$2001,(Metrics!$H$1-180+13))) -> 0 | V14: =IF((Metrics!$H$1-180+13)<1,"",INDEX(Calc_Daily!$AR$2:$AR$2001,(Metrics!$H$1-180+13))) -> 0
A15: =IF((Metrics!$H$1-180+14)<1,"",INDEX(Calc_Daily!$A$2:$A$2001,(Metrics!$H$1-180+14))) -> 0 | B15: =IF((Metrics!$H$1-180+14)<1,"",INDEX(Calc_Daily!$B$2:$B$2001,(Metrics!$H$1-180+14))) -> 0 | C15: =IF((Metrics!$H$1-180+14)<1,"",INDEX(Calc_Daily!$C$2:$C$2001,(Metrics!$H$1-180+14))) -> 0 | D15: =IF((Metrics!$H$1-180+14)<1,"",INDEX(Calc_Daily!$D$2:$D$2001,(Metrics!$H$1-180+14))) -> 0 | E15: =IF((Metrics!$H$1-180+14)<1,"",INDEX(Calc_Daily!$E$2:$E$2001,(Metrics!$H$1-180+14))) -> 0 | F15: =IF((Metrics!$H$1-180+14)<1,"",INDEX(Calc_Daily!$H$2:$H$2001,(Metrics!$H$1-180+14))) -> 0 | G15: =IF((Metrics!$H$1-180+14)<1,"",INDEX(Calc_Daily!$I$2:$I$2001,(Metrics!$H$1-180+14))) -> 0 | H15: =IF((Metrics!$H$1-180+14)<1,"",INDEX(Calc_Daily!$J$2:$J$2001,(Metrics!$H$1-180+14))) -> 0 | I15: =IF((Metrics!$H$1-180+14)<1,"",INDEX(Calc_Daily!$K$2:$K$2001,(Metrics!$H$1-180+14))) -> 0 | J15: =IF((Metrics!$H$1-180+14)<1,"",INDEX(Calc_Daily!$N$2:$N$2001,(Metrics!$H$1-180+14))) -> 0 | K15: =IF((Metrics!$H$1-180+14)<1,"",70) -> 0 | L15: =IF((Metrics!$H$1-180+14)<1,"",30) -> 0 | M15: =IF((Metrics!$H$1-180+14)<1,"",INDEX(Calc_Daily!$Q$2:$Q$2001,(Metrics!$H$1-180+14))) -> 0 | N15: =IF((Metrics!$H$1-180+14)<1,"",INDEX(Calc_Daily!$R$2:$R$2001,(Metrics!$H$1-180+14))) -> 0 | O15: =IF((Metrics!$H$1-180+14)<1,"",INDEX(Calc_Daily!$S$2:$S$2001,(Metrics!$H$1-180+14))) -> 0 | P15: =IF((Metrics!$H$1-180+14)<1,"",INDEX(Calc_Daily!$AM$2:$AM$2001,(Metrics!$H$1-180+14))) -> 0 | Q15: =IF((Metrics!$H$1-180+14)<1,"",INDEX(Calc_Daily!$AK$2:$AK$2001,(Metrics!$H$1-180+14))) -> 0 | R15: =IF((Metrics!$H$1-180+14)<1,"",INDEX(Calc_Daily!$AN$2:$AN$2001,(Metrics!$H$1-180+14))) -> 0 | S15: =IF((Metrics!$H$1-180+14)<1,"",INDEX(Calc_Daily!$AD$2:$AD$2001,(Metrics!$H$1-180+14))) -> 0 | T15: =IF((Metrics!$H$1-180+14)<1,"",INDEX(Calc_Daily!$AT$2:$AT$2001,(Metrics!$H$1-180+14))) -> 0 | U15: =IF((Metrics!$H$1-180+14)<1,"",INDEX(Calc_Daily!$AQ$2:$AQ$2001,(Metrics!$H$1-180+14))) -> 0 | V15: =IF((Metrics!$H$1-180+14)<1,"",INDEX(Calc_Daily!$AR$2:$AR$2001,(Metrics!$H$1-180+14))) -> 0
A16: =IF((Metrics!$H$1-180+15)<1,"",INDEX(Calc_Daily!$A$2:$A$2001,(Metrics!$H$1-180+15))) -> 0 | B16: =IF((Metrics!$H$1-180+15)<1,"",INDEX(Calc_Daily!$B$2:$B$2001,(Metrics!$H$1-180+15))) -> 0 | C16: =IF((Metrics!$H$1-180+15)<1,"",INDEX(Calc_Daily!$C$2:$C$2001,(Metrics!$H$1-180+15))) -> 0 | D16: =IF((Metrics!$H$1-180+15)<1,"",INDEX(Calc_Daily!$D$2:$D$2001,(Metrics!$H$1-180+15))) -> 0 | E16: =IF((Metrics!$H$1-180+15)<1,"",INDEX(Calc_Daily!$E$2:$E$2001,(Metrics!$H$1-180+15))) -> 0 | F16: =IF((Metrics!$H$1-180+15)<1,"",INDEX(Calc_Daily!$H$2:$H$2001,(Metrics!$H$1-180+15))) -> 0 | G16: =IF((Metrics!$H$1-180+15)<1,"",INDEX(Calc_Daily!$I$2:$I$2001,(Metrics!$H$1-180+15))) -> 0 | H16: =IF((Metrics!$H$1-180+15)<1,"",INDEX(Calc_Daily!$J$2:$J$2001,(Metrics!$H$1-180+15))) -> 0 | I16: =IF((Metrics!$H$1-180+15)<1,"",INDEX(Calc_Daily!$K$2:$K$2001,(Metrics!$H$1-180+15))) -> 0 | J16: =IF((Metrics!$H$1-180+15)<1,"",INDEX(Calc_Daily!$N$2:$N$2001,(Metrics!$H$1-180+15))) -> 0 | K16: =IF((Metrics!$H$1-180+15)<1,"",70) -> 0 | L16: =IF((Metrics!$H$1-180+15)<1,"",30) -> 0 | M16: =IF((Metrics!$H$1-180+15)<1,"",INDEX(Calc_Daily!$Q$2:$Q$2001,(Metrics!$H$1-180+15))) -> 0 | N16: =IF((Metrics!$H$1-180+15)<1,"",INDEX(Calc_Daily!$R$2:$R$2001,(Metrics!$H$1-180+15))) -> 0 | O16: =IF((Metrics!$H$1-180+15)<1,"",INDEX(Calc_Daily!$S$2:$S$2001,(Metrics!$H$1-180+15))) -> 0 | P16: =IF((Metrics!$H$1-180+15)<1,"",INDEX(Calc_Daily!$AM$2:$AM$2001,(Metrics!$H$1-180+15))) -> 0 | Q16: =IF((Metrics!$H$1-180+15)<1,"",INDEX(Calc_Daily!$AK$2:$AK$2001,(Metrics!$H$1-180+15))) -> 0 | R16: =IF((Metrics!$H$1-180+15)<1,"",INDEX(Calc_Daily!$AN$2:$AN$2001,(Metrics!$H$1-180+15))) -> 0 | S16: =IF((Metrics!$H$1-180+15)<1,"",INDEX(Calc_Daily!$AD$2:$AD$2001,(Metrics!$H$1-180+15))) -> 0 | T16: =IF((Metrics!$H$1-180+15)<1,"",INDEX(Calc_Daily!$AT$2:$AT$2001,(Metrics!$H$1-180+15))) -> 0 | U16: =IF((Metrics!$H$1-180+15)<1,"",INDEX(Calc_Daily!$AQ$2:$AQ$2001,(Metrics!$H$1-180+15))) -> 0 | V16: =IF((Metrics!$H$1-180+15)<1,"",INDEX(Calc_Daily!$AR$2:$AR$2001,(Metrics!$H$1-180+15))) -> 0
A17: =IF((Metrics!$H$1-180+16)<1,"",INDEX(Calc_Daily!$A$2:$A$2001,(Metrics!$H$1-180+16))) -> 0 | B17: =IF((Metrics!$H$1-180+16)<1,"",INDEX(Calc_Daily!$B$2:$B$2001,(Metrics!$H$1-180+16))) -> 0 | C17: =IF((Metrics!$H$1-180+16)<1,"",INDEX(Calc_Daily!$C$2:$C$2001,(Metrics!$H$1-180+16))) -> 0 | D17: =IF((Metrics!$H$1-180+16)<1,"",INDEX(Calc_Daily!$D$2:$D$2001,(Metrics!$H$1-180+16))) -> 0 | E17: =IF((Metrics!$H$1-180+16)<1,"",INDEX(Calc_Daily!$E$2:$E$2001,(Metrics!$H$1-180+16))) -> 0 | F17: =IF((Metrics!$H$1-180+16)<1,"",INDEX(Calc_Daily!$H$2:$H$2001,(Metrics!$H$1-180+16))) -> 0 | G17: =IF((Metrics!$H$1-180+16)<1,"",INDEX(Calc_Daily!$I$2:$I$2001,(Metrics!$H$1-180+16))) -> 0 | H17: =IF((Metrics!$H$1-180+16)<1,"",INDEX(Calc_Daily!$J$2:$J$2001,(Metrics!$H$1-180+16))) -> 0 | I17: =IF((Metrics!$H$1-180+16)<1,"",INDEX(Calc_Daily!$K$2:$K$2001,(Metrics!$H$1-180+16))) -> 0 | J17: =IF((Metrics!$H$1-180+16)<1,"",INDEX(Calc_Daily!$N$2:$N$2001,(Metrics!$H$1-180+16))) -> 0 | K17: =IF((Metrics!$H$1-180+16)<1,"",70) -> 0 | L17: =IF((Metrics!$H$1-180+16)<1,"",30) -> 0 | M17: =IF((Metrics!$H$1-180+16)<1,"",INDEX(Calc_Daily!$Q$2:$Q$2001,(Metrics!$H$1-180+16))) -> 0 | N17: =IF((Metrics!$H$1-180+16)<1,"",INDEX(Calc_Daily!$R$2:$R$2001,(Metrics!$H$1-180+16))) -> 0 | O17: =IF((Metrics!$H$1-180+16)<1,"",INDEX(Calc_Daily!$S$2:$S$2001,(Metrics!$H$1-180+16))) -> 0 | P17: =IF((Metrics!$H$1-180+16)<1,"",INDEX(Calc_Daily!$AM$2:$AM$2001,(Metrics!$H$1-180+16))) -> 0 | Q17: =IF((Metrics!$H$1-180+16)<1,"",INDEX(Calc_Daily!$AK$2:$AK$2001,(Metrics!$H$1-180+16))) -> 0 | R17: =IF((Metrics!$H$1-180+16)<1,"",INDEX(Calc_Daily!$AN$2:$AN$2001,(Metrics!$H$1-180+16))) -> 0 | S17: =IF((Metrics!$H$1-180+16)<1,"",INDEX(Calc_Daily!$AD$2:$AD$2001,(Metrics!$H$1-180+16))) -> 0 | T17: =IF((Metrics!$H$1-180+16)<1,"",INDEX(Calc_Daily!$AT$2:$AT$2001,(Metrics!$H$1-180+16))) -> 0 | U17: =IF((Metrics!$H$1-180+16)<1,"",INDEX(Calc_Daily!$AQ$2:$AQ$2001,(Metrics!$H$1-180+16))) -> 0 | V17: =IF((Metrics!$H$1-180+16)<1,"",INDEX(Calc_Daily!$AR$2:$AR$2001,(Metrics!$H$1-180+16))) -> 0
A18: =IF((Metrics!$H$1-180+17)<1,"",INDEX(Calc_Daily!$A$2:$A$2001,(Metrics!$H$1-180+17))) -> 0 | B18: =IF((Metrics!$H$1-180+17)<1,"",INDEX(Calc_Daily!$B$2:$B$2001,(Metrics!$H$1-180+17))) -> 0 | C18: =IF((Metrics!$H$1-180+17)<1,"",INDEX(Calc_Daily!$C$2:$C$2001,(Metrics!$H$1-180+17))) -> 0 | D18: =IF((Metrics!$H$1-180+17)<1,"",INDEX(Calc_Daily!$D$2:$D$2001,(Metrics!$H$1-180+17))) -> 0 | E18: =IF((Metrics!$H$1-180+17)<1,"",INDEX(Calc_Daily!$E$2:$E$2001,(Metrics!$H$1-180+17))) -> 0 | F18: =IF((Metrics!$H$1-180+17)<1,"",INDEX(Calc_Daily!$H$2:$H$2001,(Metrics!$H$1-180+17))) -> 0 | G18: =IF((Metrics!$H$1-180+17)<1,"",INDEX(Calc_Daily!$I$2:$I$2001,(Metrics!$H$1-180+17))) -> 0 | H18: =IF((Metrics!$H$1-180+17)<1,"",INDEX(Calc_Daily!$J$2:$J$2001,(Metrics!$H$1-180+17))) -> 0 | I18: =IF((Metrics!$H$1-180+17)<1,"",INDEX(Calc_Daily!$K$2:$K$2001,(Metrics!$H$1-180+17))) -> 0 | J18: =IF((Metrics!$H$1-180+17)<1,"",INDEX(Calc_Daily!$N$2:$N$2001,(Metrics!$H$1-180+17))) -> 0 | K18: =IF((Metrics!$H$1-180+17)<1,"",70) -> 0 | L18: =IF((Metrics!$H$1-180+17)<1,"",30) -> 0 | M18: =IF((Metrics!$H$1-180+17)<1,"",INDEX(Calc_Daily!$Q$2:$Q$2001,(Metrics!$H$1-180+17))) -> 0 | N18: =IF((Metrics!$H$1-180+17)<1,"",INDEX(Calc_Daily!$R$2:$R$2001,(Metrics!$H$1-180+17))) -> 0 | O18: =IF((Metrics!$H$1-180+17)<1,"",INDEX(Calc_Daily!$S$2:$S$2001,(Metrics!$H$1-180+17))) -> 0 | P18: =IF((Metrics!$H$1-180+17)<1,"",INDEX(Calc_Daily!$AM$2:$AM$2001,(Metrics!$H$1-180+17))) -> 0 | Q18: =IF((Metrics!$H$1-180+17)<1,"",INDEX(Calc_Daily!$AK$2:$AK$2001,(Metrics!$H$1-180+17))) -> 0 | R18: =IF((Metrics!$H$1-180+17)<1,"",INDEX(Calc_Daily!$AN$2:$AN$2001,(Metrics!$H$1-180+17))) -> 0 | S18: =IF((Metrics!$H$1-180+17)<1,"",INDEX(Calc_Daily!$AD$2:$AD$2001,(Metrics!$H$1-180+17))) -> 0 | T18: =IF((Metrics!$H$1-180+17)<1,"",INDEX(Calc_Daily!$AT$2:$AT$2001,(Metrics!$H$1-180+17))) -> 0 | U18: =IF((Metrics!$H$1-180+17)<1,"",INDEX(Calc_Daily!$AQ$2:$AQ$2001,(Metrics!$H$1-180+17))) -> 0 | V18: =IF((Metrics!$H$1-180+17)<1,"",INDEX(Calc_Daily!$AR$2:$AR$2001,(Metrics!$H$1-180+17))) -> 0
A19: =IF((Metrics!$H$1-180+18)<1,"",INDEX(Calc_Daily!$A$2:$A$2001,(Metrics!$H$1-180+18))) -> 0 | B19: =IF((Metrics!$H$1-180+18)<1,"",INDEX(Calc_Daily!$B$2:$B$2001,(Metrics!$H$1-180+18))) -> 0 | C19: =IF((Metrics!$H$1-180+18)<1,"",INDEX(Calc_Daily!$C$2:$C$2001,(Metrics!$H$1-180+18))) -> 0 | D19: =IF((Metrics!$H$1-180+18)<1,"",INDEX(Calc_Daily!$D$2:$D$2001,(Metrics!$H$1-180+18))) -> 0 | E19: =IF((Metrics!$H$1-180+18)<1,"",INDEX(Calc_Daily!$E$2:$E$2001,(Metrics!$H$1-180+18))) -> 0 | F19: =IF((Metrics!$H$1-180+18)<1,"",INDEX(Calc_Daily!$H$2:$H$2001,(Metrics!$H$1-180+18))) -> 0 | G19: =IF((Metrics!$H$1-180+18)<1,"",INDEX(Calc_Daily!$I$2:$I$2001,(Metrics!$H$1-180+18))) -> 0 | H19: =IF((Metrics!$H$1-180+18)<1,"",INDEX(Calc_Daily!$J$2:$J$2001,(Metrics!$H$1-180+18))) -> 0 | I19: =IF((Metrics!$H$1-180+18)<1,"",INDEX(Calc_Daily!$K$2:$K$2001,(Metrics!$H$1-180+18))) -> 0 | J19: =IF((Metrics!$H$1-180+18)<1,"",INDEX(Calc_Daily!$N$2:$N$2001,(Metrics!$H$1-180+18))) -> 0 | K19: =IF((Metrics!$H$1-180+18)<1,"",70) -> 0 | L19: =IF((Metrics!$H$1-180+18)<1,"",30) -> 0 | M19: =IF((Metrics!$H$1-180+18)<1,"",INDEX(Calc_Daily!$Q$2:$Q$2001,(Metrics!$H$1-180+18))) -> 0 | N19: =IF((Metrics!$H$1-180+18)<1,"",INDEX(Calc_Daily!$R$2:$R$2001,(Metrics!$H$1-180+18))) -> 0 | O19: =IF((Metrics!$H$1-180+18)<1,"",INDEX(Calc_Daily!$S$2:$S$2001,(Metrics!$H$1-180+18))) -> 0 | P19: =IF((Metrics!$H$1-180+18)<1,"",INDEX(Calc_Daily!$AM$2:$AM$2001,(Metrics!$H$1-180+18))) -> 0 | Q19: =IF((Metrics!$H$1-180+18)<1,"",INDEX(Calc_Daily!$AK$2:$AK$2001,(Metrics!$H$1-180+18))) -> 0 | R19: =IF((Metrics!$H$1-180+18)<1,"",INDEX(Calc_Daily!$AN$2:$AN$2001,(Metrics!$H$1-180+18))) -> 0 | S19: =IF((Metrics!$H$1-180+18)<1,"",INDEX(Calc_Daily!$AD$2:$AD$2001,(Metrics!$H$1-180+18))) -> 0 | T19: =IF((Metrics!$H$1-180+18)<1,"",INDEX(Calc_Daily!$AT$2:$AT$2001,(Metrics!$H$1-180+18))) -> 0 | U19: =IF((Metrics!$H$1-180+18)<1,"",INDEX(Calc_Daily!$AQ$2:$AQ$2001,(Metrics!$H$1-180+18))) -> 0 | V19: =IF((Metrics!$H$1-180+18)<1,"",INDEX(Calc_Daily!$AR$2:$AR$2001,(Metrics!$H$1-180+18))) -> 0
A20: =IF((Metrics!$H$1-180+19)<1,"",INDEX(Calc_Daily!$A$2:$A$2001,(Metrics!$H$1-180+19))) -> 0 | B20: =IF((Metrics!$H$1-180+19)<1,"",INDEX(Calc_Daily!$B$2:$B$2001,(Metrics!$H$1-180+19))) -> 0 | C20: =IF((Metrics!$H$1-180+19)<1,"",INDEX(Calc_Daily!$C$2:$C$2001,(Metrics!$H$1-180+19))) -> 0 | D20: =IF((Metrics!$H$1-180+19)<1,"",INDEX(Calc_Daily!$D$2:$D$2001,(Metrics!$H$1-180+19))) -> 0 | E20: =IF((Metrics!$H$1-180+19)<1,"",INDEX(Calc_Daily!$E$2:$E$2001,(Metrics!$H$1-180+19))) -> 0 | F20: =IF((Metrics!$H$1-180+19)<1,"",INDEX(Calc_Daily!$H$2:$H$2001,(Metrics!$H$1-180+19))) -> 0 | G20: =IF((Metrics!$H$1-180+19)<1,"",INDEX(Calc_Daily!$I$2:$I$2001,(Metrics!$H$1-180+19))) -> 0 | H20: =IF((Metrics!$H$1-180+19)<1,"",INDEX(Calc_Daily!$J$2:$J$2001,(Metrics!$H$1-180+19))) -> 0 | I20: =IF((Metrics!$H$1-180+19)<1,"",INDEX(Calc_Daily!$K$2:$K$2001,(Metrics!$H$1-180+19))) -> 0 | J20: =IF((Metrics!$H$1-180+19)<1,"",INDEX(Calc_Daily!$N$2:$N$2001,(Metrics!$H$1-180+19))) -> 0 | K20: =IF((Metrics!$H$1-180+19)<1,"",70) -> 0 | L20: =IF((Metrics!$H$1-180+19)<1,"",30) -> 0 | M20: =IF((Metrics!$H$1-180+19)<1,"",INDEX(Calc_Daily!$Q$2:$Q$2001,(Metrics!$H$1-180+19))) -> 0 | N20: =IF((Metrics!$H$1-180+19)<1,"",INDEX(Calc_Daily!$R$2:$R$2001,(Metrics!$H$1-180+19))) -> 0 | O20: =IF((Metrics!$H$1-180+19)<1,"",INDEX(Calc_Daily!$S$2:$S$2001,(Metrics!$H$1-180+19))) -> 0 | P20: =IF((Metrics!$H$1-180+19)<1,"",INDEX(Calc_Daily!$AM$2:$AM$2001,(Metrics!$H$1-180+19))) -> 0 | Q20: =IF((Metrics!$H$1-180+19)<1,"",INDEX(Calc_Daily!$AK$2:$AK$2001,(Metrics!$H$1-180+19))) -> 0 | R20: =IF((Metrics!$H$1-180+19)<1,"",INDEX(Calc_Daily!$AN$2:$AN$2001,(Metrics!$H$1-180+19))) -> 0 | S20: =IF((Metrics!$H$1-180+19)<1,"",INDEX(Calc_Daily!$AD$2:$AD$2001,(Metrics!$H$1-180+19))) -> 0 | T20: =IF((Metrics!$H$1-180+19)<1,"",INDEX(Calc_Daily!$AT$2:$AT$2001,(Metrics!$H$1-180+19))) -> 0 | U20: =IF((Metrics!$H$1-180+19)<1,"",INDEX(Calc_Daily!$AQ$2:$AQ$2001,(Metrics!$H$1-180+19))) -> 0 | V20: =IF((Metrics!$H$1-180+19)<1,"",INDEX(Calc_Daily!$AR$2:$AR$2001,(Metrics!$H$1-180+19))) -> 0
